Workbook
Name _CTD1: #REF!
Name _tbl: #REF!
Name _wwww: #REF!
Name arehet: #REF!
Name asgaw: #REF!
Name ATV: #REF!
Name Branch: #REF!
Name CTD: #REF!
Name EMN: #REF!
Name EMS: #REF!
Name EMS: #REF!
Name ENR: #REF!
Name Excel_BuiltIn_Print_Titles_1: #REF!
Name Excel_BuiltIn_Print_Titles_2: #REF!
Name Excel_BuiltIn_Print_Titles_3: #REF!
Name Excel_BuiltIn_Print_Titles_4: #REF!
Name HWS: #REF!
Name INS: #REF!
Name INS: #REF!
Name K_Query_Expense: [2]PTC!$C$1:$F$953
Name KERRY: #REF!
Name RCB: #REF!
Name RCV: #REF!
Name THAI: #REF!
Name บุคคลที่เกี่ยวโยง1: #REF!

Sheet Cover
B3: DETAIL OF ACCOUNT
B5: Company | C5: 0568 MP Synergy Company Limited | F5: Nature :
B6: Branch | C6: 056801-056819 MP Synergy Company Limited
B7: Account code | C7: 21930052
B8: Account name | C8: Accounts Payable-Non Trade-Subsidiaries
B9: Period | C9: 46265
C13: By CPC | E13: Per TB | F13: Per Detail | G13: Diff | H13: Remark
C16: Detail 21930052 | E16: =ROUND(SUMIF('TB 21930052'!$A$10:$A$1000000,"*Total*",'TB 21930052'!$H$10:$H$1000000),2) -> -1822374.2 | F16: =ROUND(SUMIF('TB 21930052'!$A$10:$A$1000000,"*Total*",'TB 21930052'!$I$10:$I$1000000),2) -> -1822374.2 | G16: =IFERROR($E16-$F16,"") -> 0 | I16: Detail
C18: Detail of Journal | E18: 0 | F18: =ROUND(SUMIF('TB 21930052'!$A$10:$A$1000000,"*Total*",'TB 21930052'!$K$10:$K$1000000),2) -> 0 | G18: =IFERROR($E18-$F18,"") -> 0
C20: Detail of Convert AP | E20: 0 | F20: =ROUND(SUMIF('TB 21930052'!$A$10:$A$1000000,"*Total*",'TB 21930052'!$J$10:$J$1000000),2) -> 0 | G20: =IFERROR($E20-$F20,"") -> 0
C23: Diff | E23: =SUM(E14:E22) -> -1822374.2 | F23: =SUM(F14:F22) -> -1822374.2 | G23: =SUM(G14:G22) -> 0
B28: APN
B30: Prepare by : | F30: Review by :
C31: AP Controller | J31: (ระบุชื่อ - นามสกุล)
J32: (ระบุตำแหน่ง)
B33: Date : | F33: Date :

Sheet TB 21930052
A1: DETAIL OF ACCOUNT
A3: Company | B3: 0568 MP Synergy Company Limited
A4: Branch | B4: 056801-056819 MP Synergy Company Limited
A5: Account code | B5: 21930052
A6: Account name | B6: Accounts Payable-Non Trade-Subsidiaries
A7: Period | B7: 46265
A9: Branch | B9: CPC | C9: Account | D9: SubAcc | E9: Description | F9: Beginnging Balance | G9: Period Activity | H9: Ending Balance | I9: AP Outstanding | J9: Convert AP | K9: Journal ADJ. | L9: Summary AP | M9: Diff (AP-T/B) | N9: หมายเหตุ
A10: 056801 | B10: 99999 | C10: 21930052 | D10: 018530 | E10: Accounts Payable-Non T | F10: 0 | G10: -50998.78 | H10: -50998.78 | I10: =-SUMIFS('Accounts Payable Trial Balance'!$I$20:$I$1000000,'Accounts Payable Trial Balance'!$A$20:$A$1000000,$A10,'Accounts Payable Trial Balance'!$C$20:$C$1000000,$D10) -> -50998.78 | L10: =SUM($I10:$K10) -> -50998.78 | M10: =+$H10-$L10 -> 0
A11: 056801 | B11: 99999 | C11: 21930052 | D11: 050901 | E11: Accounts Payable-Non T | F11: 0 | G11: -1262.5 | H11: -1262.5 | I11: =-SUMIFS('Accounts Payable Trial Balance'!$I$20:$I$1000000,'Accounts Payable Trial Balance'!$A$20:$A$1000000,$A11,'Accounts Payable Trial Balance'!$C$20:$C$1000000,$D11) -> -1262.5 | L11: =SUM($I11:$K11) -> -1262.5 | M11: =+$H11-$L11 -> 0
A12: 056801 | B12: 99999 | C12: 21930052 | D12: 055099 | E12: Accounts Payable-Non T | F12: -57.5 | G12: 10.51 | H12: -46.99 | I12: =-SUMIFS('Accounts Payable Trial Balance'!$I$20:$I$1000000,'Accounts Payable Trial Balance'!$A$20:$A$1000000,$A12,'Accounts Payable Trial Balance'!$C$20:$C$1000000,$D12) -> -46.99 | L12: =SUM($I12:$K12) -> -46.99 | M12: =+$H12-$L12 -> 0
A13: 056801 | B13: 99999 | C13: 21930052 | D13: 056001 | E13: Accounts Payable-Non T | F13: -5018.91 | G13: -9721.58 | H13: -14740.49 | I13: =-SUMIFS('Accounts Payable Trial Balance'!$I$20:$I$1000000,'Accounts Payable Trial Balance'!$A$20:$A$1000000,$A13,'Accounts Payable Trial Balance'!$C$20:$C$1000000,$D13) -> -14740.49 | L13: =SUM($I13:$K13) -> -14740.49 | M13: =+$H13-$L13 -> 0
A14: 056801 | B14: 99999 | C14: 21930052 | D14: 056059 | E14: Accounts Payable-Non T | F14: -144904.32 | G14: 144904.32 | H14: 0 | I14: =-SUMIFS('Accounts Payable Trial Balance'!$I$20:$I$1000000,'Accounts Payable Trial Balance'!$A$20:$A$1000000,$A14,'Accounts Payable Trial Balance'!$C$20:$C$1000000,$D14) -> 0 | L14: =SUM($I14:$K14) -> 0 | M14: =+$H14-$L14 -> 0
A15: 056801 | B15: 99999 | C15: 21930052 | D15: 0560B9 | E15: Accounts Payable-Non T | F15: -35000 | G15: 0 | H15: -35000 | I15: =-SUMIFS('Accounts Payable Trial Balance'!$I$20:$I$1000000,'Accounts Payable Trial Balance'!$A$20:$A$1000000,$A15,'Accounts Payable Trial Balance'!$C$20:$C$1000000,$D15) -> -35000 | L15: =SUM($I15:$K15) -> -35000 | M15: =+$H15-$L15 -> 0
A16: 056801 | B16: 99999 | C16: 21930052 | D16: 0560H2 | E16: Accounts Payable-Non T | F16: -1212.61 | G16: 906.22 | H16: -306.39 | I16: =-SUMIFS('Accounts Payable Trial Balance'!$I$20:$I$1000000,'Accounts Payable Trial Balance'!$A$20:$A$1000000,$A16,'Accounts Payable Trial Balance'!$C$20:$C$1000000,$D16) -> -306.39 | L16: =SUM($I16:$K16) -> -306.39 | M16: =+$H16-$L16 -> 0
A17: 056801 | B17: 99999 | C17: 21930052 | D17: 056602 | E17: Accounts Payable-Non T | F17: 0 | G17: -1174288.1 | H17: -1174288.1 | I17: =-SUMIFS('Accounts Payable Trial Balance'!$I$20:$I$1000000,'Accounts Payable Trial Balance'!$A$20:$A$1000000,$A17,'Accounts Payable Trial Balance'!$C$20:$C$1000000,$D17) -> -1174288.1 | L17: =SUM($I17:$K17) -> -1174288.1 | M17: =+$H17-$L17 -> 0
A18: 056801 | B18: 99999 | C18: 21930052 | D18: 070101 | E18: Accounts Payable-Non T | F18: -15172.6 | G18: 15172.6 | H18: 0 | I18: =-SUMIFS('Accounts Payable Trial Balance'!$I$20:$I$1000000,'Accounts Payable Trial Balance'!$A$20:$A$1000000,$A18,'Accounts Payable Trial Balance'!$C$20:$C$1000000,$D18) -> 0 | L18: =SUM($I18:$K18) -> 0 | M18: =+$H18-$L18 -> 0
A19: 056801 | B19: 99999 | C19: 21930052 | D19: 019701 | E19: Accounts Payable-Non T | F19: 0 | G19: 0 | H19: 0 | I19: =-SUMIFS('Accounts Payable Trial Balance'!$I$20:$I$1000000,'Accounts Payable Trial Balance'!$A$20:$A$1000000,$A19,'Accounts Payable Trial Balance'!$C$20:$C$1000000,$D19) -> 0 | L19: =SUM($I19:$K19) -> 0 | M19: =+$H19-$L19 -> 0 | N19: Notfound!!! -- TB
A20: 056801 | B20: 99999 | C20: 21930052 | D20: 019911 | E20: Accounts Payable-Non T | F20: 0 | G20: 0 | H20: 0 | I20: =-SUMIFS('Accounts Payable Trial Balance'!$I$20:$I$1000000,'Accounts Payable Trial Balance'!$A$20:$A$1000000,$A20,'Accounts Payable Trial Balance'!$C$20:$C$1000000,$D20) -> 0 | L20: =SUM($I20:$K20) -> 0 | M20: =+$H20-$L20 -> 0 | N20: Notfound!!! -- TB
A21: 056807 | B21: 99999 | C21: 21930052 | D21: 019911 | E21: Accounts Payable-Non T | F21: -76130.71 | G21: 63727.78 | H21: -12402.93 | I21: =-SUMIFS('Accounts Payable Trial Balance'!$I$20:$I$1000000,'Accounts Payable Trial Balance'!$A$20:$A$1000000,$A21,'Accounts Payable Trial Balance'!$C$20:$C$1000000,$D21) -> -12402.93 | L21: =SUM($I21:$K21) -> -12402.93 | M21: =+$H21-$L21 -> 0
A22: 056813 | B22: 99999 | C22: 21930052 | D22: 018410 | E22: Accounts Payable-Non T | F22: -229460.75 | G22: -67106.52 | H22: -296567.27 | I22: =-SUMIFS('Accounts Payable Trial Balance'!$I$20:$I$1000000,'Accounts Payable Trial Balance'!$A$20:$A$1000000,$A22,'Accounts Payable Trial Balance'!$C$20:$C$1000000,$D22) -> -296567.27 | L22: =SUM($I22:$K22) -> -296567.27 | M22: =+$H22-$L22 -> 0
A23: 056818 | B23: 99999 | C23: 21930052 | D23: 018519 | E23: Accounts Payable-Non T | F23: -147287.63 | G23: 64026.83 | H23: -83260.8 | I23: =-SUMIFS('Accounts Payable Trial Balance'!$I$20:$I$1000000,'Accounts Payable Trial Balance'!$A$20:$A$1000000,$A23,'Accounts Payable Trial Balance'!$C$20:$C$1000000,$D23) -> -83260.8 | L23: =SUM($I23:$K23) -> -83260.8 | M23: =+$H23-$L23 -> 0
A24: 056819 | B24: 99999 | C24: 21930052 | D24: 018513 | E24: Accounts Payable-Non T | F24: -153284.1 | G24: -215.84 | H24: -153499.94 | I24: =-SUMIFS('Accounts Payable Trial Balance'!$I$20:$I$1000000,'Accounts Payable Trial Balance'!$A$20:$A$1000000,$A24,'Accounts Payable Trial Balance'!$C$20:$C$1000000,$D24) -> -153499.94 | L24: =SUM($I24:$K24) -> -153499.94 | M24: =+$H24-$L24 -> 0
A25: Total | F25: =SUM(F$10:F24) -> -807529.13 | G25: =SUM(G$10:G24) -> -1014845.1 | H25: =SUM(H$10:H24) -> -1822374.2 | I25: =SUM(I$10:I24) -> -1822374.2 | J25: =SUM(J$10:J24) -> 0 | K25: =SUM(K$10:K24) -> 0 | L25: =SUM(L$10:L24) -> -1822374.2 | M25: =SUM(M$10:M24) -> 0

Sheet Accounts Payable Trial Balance
A1: MPS BOOK Report Date: 10-SEP-2026
A3: Accounts Payable Trial Balance Summary(New) (Custom)
A5: Reporting Level: Operating Unit
A6: Reporting Context: MPS Operation Unit
A7: Accounting Currency: THB
A8: As of Date: 31-AUG-26
A9: Branch From: 056801
A10: Branch To: 056819
A11: Supplier Name: All
A12: Liability Account From: 1-05-0568-056801-99999-21930052-018530
A13: Liability Account To: 1-05-0568-056819-99999-21930052-018513
A14: Summarize Report: No
... A17: Show Supplier Summary : No
A19: Branch | B19: Account | C19: SubAcc | D19: Supplier Number &Name | E19: Invoice Number | F19: Invoice Date | G19: Curr | H19: Amount | I19: Remaining Amount | J19: Invoice Description
A20: 056801 | B20: 21930052 | C20: 018530 | D20: N-155227 : เซ็นทรัลพัฒนา บมจ. (สาขาที่ 00026) | E20: 2025-1100213953 | F20: 31-AUG-26 | G20: THB | H20: 4832.26 | I20: 4832.26 | J20: 28-31/08/2026 ค่าบริการสถานที่
A21: 056801 | B21: 21930052 | C21: 018530 | D21: N-155227 : เซ็นทรัลพัฒนา บมจ. (สาขาที่ 00026) | E21: 2026-1100213958 | F21: 31-AUG-26 | G21: THB | H21: 1626.69 | I21: 1626.69 | J21: 28.08-27.11.2026 ค่าเบี้ยประกันภัยพื้นที่
A22: 056801 | B22: 21930052 | C22: 018530 | D22: N-155227 : เซ็นทรัลพัฒนา บมจ. (สาขาที่ 00026) | E22: 2025-1100213959 | F22: 31-AUG-26 | G22: THB | H22: 37450 | I22: 37450 | J22: 01-30/09/2026 ค่าบริการสถานที่
A23: 056801 | B23: 21930052 | C23: 018530 | D23: N-155227 : เซ็นทรัลพัฒนา บมจ. (สาขาที่ 00026) | E23: 2026-1100213956 | F23: 31-AUG-26 | G23: THB | H23: 7089.83 | I23: 7089.83 | J23: 28.08-27.11.2026 ค่าภาษีที่ดินและสิ่งปลูกสร้าง
A24: 056801 | B24: 21930052 | C24: 019701 | D24: N-112087 : เซ็นทรัลพัฒนา ไนน์ สแควร์ บจก. | E24: 2025-20500082/CN | F24: 06-JUN-25 | G24: THB | H24: -10700 | I24: -10700 | J24: 20/04/2025-01/05/2025 เงินประกันความเสียหาย สัญญาเลข
A25: 056801 | B25: 21930052 | C25: 019701 | D25: N-112087 : เซ็นทรัลพัฒนา ไนน์ สแควร์ บจก. | E25: 2025-20500082 | F25: 06-JUN-25 | G25: THB | H25: 10700 | I25: 10700 | J25: 20/04/2025-01/05/2025 เงินประกันความเสียหาย สัญญาเลข
A26: 056801 | B26: 21930052 | C26: 019911 | D26: N-141705 : ซีพีเอ็น วิลเลจ บจก. สาขาที่ 00001 | E26: 2025-1010000175/B | F26: 09-APR-26 | G26: THB | H26: 10000 | I26: 10000 | J26: 05/08/2025-05/08/2025 เงินมัดจำค่าเช่า สัญญาเลขที่ S
A27: 056801 | B27: 21930052 | C27: 019911 | D27: N-141705 : ซีพีเอ็น วิลเลจ บจก. สาขาที่ 00001 | E27: 2025-1010000175/CN | F27: 09-APR-26 | G27: THB | H27: -10000 | I27: -10000 | J27: ใบลดหนี้ 05/08/2025-05/08/2025 เงินมัดจำค่าเช่า สัญญ
A28: 056801 | B28: 21930052 | C28: 050901 | D28: N-109213 : บีทูเอส บจก. สำนักงานใหญ่ | E28: A6801/S0901IN2608133 | F28: 18-AUG-26 | G28: THB | H28: 1186.73 | I28: 1186.73 | J28: ค่าบริการอื่น ๆ จากการดำเนินงาน -บริษัทในเครือ 044_0
A29: 056801 | B29: 21930052 | C29: 050901 | D29: N-109213 : บีทูเอส บจก. สำนักงานใหญ่ | E29: A6801/S0901IN2608133 | F29: 18-AUG-26 | G29: THB | H29: 75.77 | I29: 75.77 | J29: ค่าบริการอื่น ๆ จากการดำเนินงาน -บริษัทในเครือ 044_0
A30: 056801 | B30: 21930052 | C30: 055099 | D30: N-111693 : เพาเวอร์บาย บจก. สาขาคลังสินค้า | E30: A6801/S5099IN2608090 | F30: 28-AUG-26 | G30: THB | H30: 24.29 | I30: 24.29 | J30: ค่าบริการอื่น ๆ จากการดำเนินงาน -บริษัทในเครือ CO.24
A31: 056801 | B31: 21930052 | C31: 055099 | D31: N-111693 : เพาเวอร์บาย บจก. สาขาคลังสินค้า | E31: A6801/S5099IN2608090 | F31: 28-AUG-26 | G31: THB | H31: 22.7 | I31: 22.7 | J31: Rebate อื่น-เก็บเงินตามยอดขาย บริษัทในเครือ(ใหม่) CO
... A36: 056801 | B36: 21930052 | C36: 0560H2 | D36: N-145909 : ออฟฟิศเมท (ไทย) บจก.(Head Office 2) | E36: A6801/S60H2IN2608304 | F36: 26-AUG-26 | G36: THB | H36: 306.39 | I36: 306.39 | J36: ค่าบริการอื่น ๆ จากการดำเนินงาน -บริษัทในเครือ 044_0
A37: 056801 Total | H37: =SUBTOTAL(9,H20:H36) -> 1276643.3 | I37: =SUBTOTAL(9,I20:I36) -> 1276643.3
A38: 056807 | B38: 21930052 | C38: 019911 | D38: N-141705 : ซีพีเอ็น วิลเลจ บจก. สาขาที่ 00001 | E38: 2026-2010002014 | F38: 27-AUG-26 | G38: THB | H38: 12402.93 | I38: 12402.93 | J38: 10/07-10/08/2026 (S) ค่าไฟฟ้า (บริษัทในเครือ) สัญญาเ
A39: 056807 Total | H39: =SUBTOTAL(9,H38:H38) -> 12402.93 | I39: =SUBTOTAL(9,I38:I38) -> 12402.93
A40: 056813 | B40: 21930052 | C40: 018410 | D40: N-131484 : ทรัสต์เพื่อการลงทุนในสิทธิการเช่าอสังหาริมทรัพย์ | E40: 2026-1100046587/1 | F40: 28-AUG-26 | G40: THB | H40: 133926.51 | I40: 133926.51 | J40: 01-30/09/2026 ค่าเช่าพื้นที่ เลขที่สัญญา RM225520600
A41: 056813 | B41: 21930052 | C41: 018410 | D41: N-131484 : ทรัสต์เพื่อการลงทุนในสิทธิการเช่าอสังหาริมทรัพย์ | E41: 2026-2010015126 | F41: 28-AUG-26 | G41: THB | H41: 7733.4 | I41: 7733.4 | J41: 10/07/2026-10/08/2026 ค่าไฟฟ้าเลขที่สัญญา RM22552060
A42: 056813 | B42: 21930052 | C42: 018410 | D42: N-131484 : ทรัสต์เพื่อการลงทุนในสิทธิการเช่าอสังหาริมทรัพย์ | E42: 2026-1100046587 | F42: 28-AUG-26 | G42: THB | H42: 95534.24 | I42: 95534.24 | J42: 01-30/09/2026 ค่าบริการงานระบบ เลขที่สัญญา RM2255206
A43: 056813 | B43: 21930052 | C43: 018410 | D43: N-131484 : ทรัสต์เพื่อการลงทุนในสิทธิการเช่าอสังหาริมทรัพย์ | E43: 2026-1100046968 | F43: 28-AUG-26 | G43: THB | H43: 59373.12 | I43: 59373.12 | J43: 01-30/09/2026 ค่าบริการ เลขที่สัญญา RM22552060082 ร้
A44: 056813 Total | H44: =SUBTOTAL(9,H40:H43) -> 296567.27 | I44: =SUBTOTAL(9,I40:I43) -> 296567.27
A45: 056818 | B45: 21930052 | C45: 018519 | D45: N-126519 : เซ็นทรัลพัฒนา บมจ. (สาขาที่00014) | E45: 2026-1100200354 | F45: 27-AUG-26 | G45: THB | H45: 29271.72 | I45: 29271.72 | J45: 01-30/09/2026 ค่าบริการ (บริษัทในเครือ) (S3) สัญญาเล
A46: 056818 | B46: 21930052 | C46: 018519 | D46: N-126519 : เซ็นทรัลพัฒนา บมจ. (สาขาที่00014) | E46: 2026-1100198868/1 | F46: 27-AUG-26 | G46: THB | H46: 45976.66 | I46: 45976.66 | J46: 01-30/09/2026 (S3) ค่าบริการงานระบบ (บริษัทในเครือ)
A47: 056818 | B47: 21930052 | C47: 018519 | D47: N-126519 : เซ็นทรัลพัฒนา บมจ. (สาขาที่00014) | E47: 2026-2010112895 | F47: 27-AUG-26 | G47: THB | H47: 8012.42 | I47: 8012.42 | J47: 10/07-10/08/2026 (S) ค่าไฟฟ้า (บริษัทในเครือ) สัญญาเ
A48: 056818 Total | H48: =SUBTOTAL(9,H45:H47) -> 83260.8 | I48: =SUBTOTAL(9,I45:I47) -> 83260.8
A49: 056819 | B49: 21930052 | C49: 018513 | D49: N-112602 : เซ็นทรัลพัฒนา บมจ. (สาขาที่00008) | E49: 2026-1100197186 | F49: 27-AUG-26 | G49: THB | H49: 31279.36 | I49: 31279.36 | J49: 01-30/09/2026 ค่าบริการ (บริษัทในเครือ) สัญญาเลขที่
...
